2020-06-09 22:29:56,460:INFO:main  — Main script started
2020-06-09 22:29:56,460:INFO:main  — Main Script finished
2020-06-09 22:29:56,460:INFO:cleanup  — Log file cleanup starting 
2020-06-09 22:29:56,460:INFO:cleanup  — Sucessfully deleted 0 file(s)
2020-06-09 22:29:56,464:INFO:cleanup  — Log file cleanup finished.
2020-06-09 22:29:56,464:INFO:backup  — Starting SBC backups 
2020-06-09 22:29:56,693:INFO:backup  — Backup of m-cba-nsw-bellavista-sbc01 completed
2020-06-09 22:29:56,922:INFO:backup  — Backup of m-cba-nsw-bellavista-sbc02 completed
2020-06-09 22:30:17,935:ERROR:backup  — An Exception Occured
Traceback (most recent call last):
  File "C:\nora\main.py", line 67, in backup
    sftp=pysftp.Connection(ip_address,username=SBC_SFTP_USER,private_key=PRIVATE_KEY_PATH,cnopts=cnopts)
  File "C:\Program Files\Python38\lib\site-packages\pysftp\__init__.py", line 140, in __init__
    self._start_transport(host, port)
  File "C:\Program Files\Python38\lib\site-packages\pysftp\__init__.py", line 176, in _start_transport
    self._transport = paramiko.Transport((host, port))
  File "C:\Program Files\Python38\lib\site-packages\paramiko\transport.py", line 415, in __init__
    raise SSHException(
paramiko.ssh_exception.SSHException: Unable to connect to 10.10.1.14: [WinError 10060] A connection attempt failed because the connected party did not properly respond after a period of time, or established connection failed because connected host has failed to respond
2020-06-12 11:42:49,899:INFO:main  — Main script started
2020-06-12 11:42:49,899:INFO:main  — Main Script finished
2020-06-12 11:42:49,899:ERROR:main  — An Exception Occured
Traceback (most recent call last):
  File "C:\nora\main.py", line 118, in main
    reports("05/06/2020 00:00","07/06/2020 00:00")
TypeError: reports() missing 1 required positional argument: 'root_path'
2020-06-12 11:43:31,099:INFO:main  — Main script started
2020-06-12 11:43:31,103:INFO:main  — Main Script finished
2020-06-12 11:43:31,103:ERROR:main  — An Exception Occured
Traceback (most recent call last):
  File "C:\nora\main.py", line 118, in main
    reports("05/06/2020 00:00","07/06/2020 00:00")
TypeError: reports() missing 1 required positional argument: 'root_path'
2020-06-12 11:44:35,169:INFO:main  — Main script started
2020-06-12 11:44:35,169:INFO:main  — Main Script finished
2020-06-12 11:44:35,185:ERROR:main  — An Exception Occured
Traceback (most recent call last):
  File "C:\nora\main.py", line 118, in main
    reports("05/06/2020 00:00","07/06/2020 00:00","K:\\")
  File "C:\nora\main.py", line 91, in reports
    begin_epoch = int(time.mktime(time.strptime(begin_datetime, pattern)))
  File "C:\Program Files\Python38\lib\_strptime.py", line 562, in _strptime_time
    tt = _strptime(data_string, format)[0]
  File "C:\Program Files\Python38\lib\_strptime.py", line 349, in _strptime
    raise ValueError("time data %r does not match format %r" %
ValueError: time data '05/06/2020 00:00' does not match format '%d.%m.%Y %H:%M:%S'
2020-06-12 11:45:40,327:INFO:main  — Main script started
2020-06-12 11:45:40,327:INFO:main  — Main Script finished
2020-06-12 11:45:40,331:INFO:reports  — Search fils starting 
2020-06-12 11:45:40,499:ERROR:reports  — An Exception Occured
Traceback (most recent call last):
  File "C:\nora\main.py", line 104, in reports
    count+=1
UnboundLocalError: local variable 'count' referenced before assignment
2020-06-12 11:46:15,614:INFO:main  — Main script started
2020-06-12 11:46:15,614:INFO:main  — Main Script finished
2020-06-12 11:46:15,618:INFO:reports  — Search fils starting 
2020-06-12 11:46:15,642:ERROR:reports  — An Exception Occured
Traceback (most recent call last):
  File "C:\nora\main.py", line 104, in reports
    count+=1
UnboundLocalError: local variable 'count' referenced before assignment
2020-06-12 11:48:05,941:INFO:main  — Main script started
2020-06-12 11:48:05,941:INFO:main  — Main Script finished
2020-06-12 11:48:05,941:INFO:reports  — Search fils starting 
2020-06-12 11:48:05,962:ERROR:reports  — An Exception Occured
Traceback (most recent call last):
  File "C:\nora\main.py", line 104, in reports
    count+=1
UnboundLocalError: local variable 'count' referenced before assignment
2020-06-12 11:49:53,155:INFO:main  — Main script started
2020-06-12 11:49:53,155:INFO:main  — Main Script finished
2020-06-12 11:49:53,159:INFO:reports  — Search fils starting 
2020-06-12 11:49:53,491:ERROR:reports  — An Exception Occured
Traceback (most recent call last):
  File "C:\nora\main.py", line 104, in reports
    count+=1
UnboundLocalError: local variable 'count' referenced before assignment
2020-06-12 11:50:59,027:INFO:main  — Main script started
2020-06-12 11:50:59,027:INFO:main  — Main Script finished
2020-06-12 11:50:59,031:INFO:reports  — Search fils starting 
2020-06-12 11:53:13,309:ERROR:reports  — An Exception Occured
Traceback (most recent call last):
  File "C:\nora\main.py", line 104, in reports
    print(full_path)
  File "C:\Program Files\Python38\lib\idlelib\run.py", line 437, in write
    return self.shell.write(s, self.tags)
  File "C:\Program Files\Python38\lib\idlelib\rpc.py", line 607, in __call__
    value = self.sockio.remotecall(self.oid, self.name, args, kwargs)
  File "C:\Program Files\Python38\lib\idlelib\rpc.py", line 219, in remotecall
    return self.asyncreturn(seq)
  File "C:\Program Files\Python38\lib\idlelib\rpc.py", line 248, in asyncreturn
    response = self.getresponse(seq, wait=0.05)
  File "C:\Program Files\Python38\lib\idlelib\rpc.py", line 291, in getresponse
    response = self._getresponse(myseq, wait)
  File "C:\Program Files\Python38\lib\idlelib\rpc.py", line 319, in _getresponse
    cvar.wait()
  File "C:\Program Files\Python38\lib\threading.py", line 302, in wait
    waiter.acquire()
KeyboardInterrupt
2020-06-12 11:54:35,514:INFO:main  — Main script started
2020-06-12 11:54:35,514:INFO:main  — Main Script finished
2020-06-12 11:54:35,518:INFO:reports  — Search fils starting 
2020-06-12 11:54:35,522:INFO:reports  — Found 0 file(s)
