2020-07-05 21:42:06,775 [INFO] [<module>]  **** repports script started ****
2020-07-05 21:42:06,775 [INFO] [reports]  Search for file(s) starting 
2020-07-05 21:42:06,775 [INFO] [reports]  Found 0 file(s)
2020-07-05 21:42:06,779 [INFO] [reports]  Loading file(s) starting 
2020-07-05 21:42:06,779 [ERROR] [reports]  An Exception Occured
Traceback (most recent call last):
  File "C:\nora\reports.py", line 46, in reports
    df=pd.concat((pd.read_csv(file,usecols=['TimeStamp','CPU Utilization','Memory Utilization','Signaling Sessions']) for file in file_list))
  File "C:\Program Files\Python38\lib\site-packages\pandas\core\reshape\concat.py", line 271, in concat
    op = _Concatenator(
  File "C:\Program Files\Python38\lib\site-packages\pandas\core\reshape\concat.py", line 329, in __init__
    raise ValueError("No objects to concatenate")
ValueError: No objects to concatenate
2020-07-05 21:42:06,779 [INFO] [reports]  Writing report to file - K:\TEST\{name}.csv
2020-07-05 21:42:06,779 [ERROR] [reports]  An Exception Occured
Traceback (most recent call last):
  File "C:\nora\reports.py", line 67, in reports
    df.to_csv(device_name)
UnboundLocalError: local variable 'df' referenced before assignment
2020-07-05 21:42:06,779 [INFO] [reports]  Search for file(s) starting 
2020-07-05 21:42:06,779 [INFO] [reports]  Found 0 file(s)
2020-07-05 21:42:06,779 [INFO] [reports]  Loading file(s) starting 
2020-07-05 21:42:06,779 [ERROR] [reports]  An Exception Occured
Traceback (most recent call last):
  File "C:\nora\reports.py", line 46, in reports
    df=pd.concat((pd.read_csv(file,usecols=['TimeStamp','CPU Utilization','Memory Utilization','Signaling Sessions']) for file in file_list))
  File "C:\Program Files\Python38\lib\site-packages\pandas\core\reshape\concat.py", line 271, in concat
    op = _Concatenator(
  File "C:\Program Files\Python38\lib\site-packages\pandas\core\reshape\concat.py", line 329, in __init__
    raise ValueError("No objects to concatenate")
ValueError: No objects to concatenate
2020-07-05 21:42:06,779 [INFO] [reports]  Writing report to file - K:\TEST\{name}.csv
2020-07-05 21:42:06,783 [ERROR] [reports]  An Exception Occured
Traceback (most recent call last):
  File "C:\nora\reports.py", line 67, in reports
    df.to_csv(device_name)
UnboundLocalError: local variable 'df' referenced before assignment
2020-07-05 21:42:06,783 [INFO] [reports]  Search for file(s) starting 
2020-07-05 21:42:06,783 [INFO] [reports]  Found 0 file(s)
2020-07-05 21:42:06,783 [INFO] [reports]  Loading file(s) starting 
2020-07-05 21:42:06,783 [ERROR] [reports]  An Exception Occured
Traceback (most recent call last):
  File "C:\nora\reports.py", line 46, in reports
    df=pd.concat((pd.read_csv(file,usecols=['TimeStamp','CPU Utilization','Memory Utilization','Signaling Sessions']) for file in file_list))
  File "C:\Program Files\Python38\lib\site-packages\pandas\core\reshape\concat.py", line 271, in concat
    op = _Concatenator(
  File "C:\Program Files\Python38\lib\site-packages\pandas\core\reshape\concat.py", line 329, in __init__
    raise ValueError("No objects to concatenate")
ValueError: No objects to concatenate
2020-07-05 21:42:06,783 [INFO] [reports]  Writing report to file - K:\TEST\{name}.csv
2020-07-05 21:42:06,783 [ERROR] [reports]  An Exception Occured
Traceback (most recent call last):
  File "C:\nora\reports.py", line 67, in reports
    df.to_csv(device_name)
UnboundLocalError: local variable 'df' referenced before assignment
2020-07-05 21:42:06,783 [INFO] [reports]  Search for file(s) starting 
2020-07-05 21:42:06,783 [INFO] [reports]  Found 0 file(s)
2020-07-05 21:42:06,783 [INFO] [reports]  Loading file(s) starting 
2020-07-05 21:42:06,783 [ERROR] [reports]  An Exception Occured
Traceback (most recent call last):
  File "C:\nora\reports.py", line 46, in reports
    df=pd.concat((pd.read_csv(file,usecols=['TimeStamp','CPU Utilization','Memory Utilization','Signaling Sessions']) for file in file_list))
  File "C:\Program Files\Python38\lib\site-packages\pandas\core\reshape\concat.py", line 271, in concat
    op = _Concatenator(
  File "C:\Program Files\Python38\lib\site-packages\pandas\core\reshape\concat.py", line 329, in __init__
    raise ValueError("No objects to concatenate")
ValueError: No objects to concatenate
2020-07-05 21:42:06,783 [INFO] [reports]  Writing report to file - K:\TEST\{name}.csv
2020-07-05 21:42:06,783 [ERROR] [reports]  An Exception Occured
Traceback (most recent call last):
  File "C:\nora\reports.py", line 67, in reports
    df.to_csv(device_name)
UnboundLocalError: local variable 'df' referenced before assignment
2020-07-05 21:42:06,783 [INFO] [reports]  Search for file(s) starting 
2020-07-05 21:42:06,783 [INFO] [reports]  Found 0 file(s)
2020-07-05 21:42:06,787 [INFO] [reports]  Loading file(s) starting 
2020-07-05 21:42:06,787 [ERROR] [reports]  An Exception Occured
Traceback (most recent call last):
  File "C:\nora\reports.py", line 46, in reports
    df=pd.concat((pd.read_csv(file,usecols=['TimeStamp','CPU Utilization','Memory Utilization','Signaling Sessions']) for file in file_list))
  File "C:\Program Files\Python38\lib\site-packages\pandas\core\reshape\concat.py", line 271, in concat
    op = _Concatenator(
  File "C:\Program Files\Python38\lib\site-packages\pandas\core\reshape\concat.py", line 329, in __init__
    raise ValueError("No objects to concatenate")
ValueError: No objects to concatenate
2020-07-05 21:42:06,787 [INFO] [reports]  Writing report to file - K:\TEST\{name}.csv
2020-07-05 21:42:06,787 [ERROR] [reports]  An Exception Occured
Traceback (most recent call last):
  File "C:\nora\reports.py", line 67, in reports
    df.to_csv(device_name)
UnboundLocalError: local variable 'df' referenced before assignment
2020-07-05 21:42:06,787 [INFO] [reports]  Search for file(s) starting 
2020-07-05 21:42:06,787 [INFO] [reports]  Found 0 file(s)
2020-07-05 21:42:06,787 [INFO] [reports]  Loading file(s) starting 
2020-07-05 21:42:06,787 [ERROR] [reports]  An Exception Occured
Traceback (most recent call last):
  File "C:\nora\reports.py", line 46, in reports
    df=pd.concat((pd.read_csv(file,usecols=['TimeStamp','CPU Utilization','Memory Utilization','Signaling Sessions']) for file in file_list))
  File "C:\Program Files\Python38\lib\site-packages\pandas\core\reshape\concat.py", line 271, in concat
    op = _Concatenator(
  File "C:\Program Files\Python38\lib\site-packages\pandas\core\reshape\concat.py", line 329, in __init__
    raise ValueError("No objects to concatenate")
ValueError: No objects to concatenate
2020-07-05 21:42:06,787 [INFO] [reports]  Writing report to file - K:\TEST\{name}.csv
2020-07-05 21:42:06,787 [ERROR] [reports]  An Exception Occured
Traceback (most recent call last):
  File "C:\nora\reports.py", line 67, in reports
    df.to_csv(device_name)
UnboundLocalError: local variable 'df' referenced before assignment
2020-07-05 21:42:06,787 [INFO] [<module>]  Main Script finished
2020-07-05 21:43:40,157 [INFO] [<module>]  **** repports script started ****
2020-07-05 21:43:40,181 [INFO] [<module>]  Main Script finished
2020-07-05 21:50:32,728 [INFO] [<module>]  **** repports script started ****
2020-07-05 21:50:32,746 [INFO] [reports]  search for file(s) starting 
2020-07-05 21:50:32,746 [INFO] [reports]  Found 0 file(s)
2020-07-05 21:50:32,746 [INFO] [reports]  Loading file(s) starting 
2020-07-05 21:50:32,746 [ERROR] [reports]  An Exception Occured
Traceback (most recent call last):
  File "C:\nora\reports.py", line 53, in reports
    df=pd.concat((pd.read_csv(file,usecols=['TimeStamp','CPU Utilization','Memory Utilization','Signaling Sessions']) for file in file_list))
  File "C:\Program Files\Python38\lib\site-packages\pandas\core\reshape\concat.py", line 271, in concat
    op = _Concatenator(
  File "C:\Program Files\Python38\lib\site-packages\pandas\core\reshape\concat.py", line 329, in __init__
    raise ValueError("No objects to concatenate")
ValueError: No objects to concatenate
2020-07-05 21:50:32,750 [INFO] [reports]  Writing report to file - K:\TEST\{name}.csv
2020-07-05 21:50:32,750 [ERROR] [reports]  An Exception Occured
Traceback (most recent call last):
  File "C:\nora\reports.py", line 74, in reports
    df.to_csv(device_name)
UnboundLocalError: local variable 'df' referenced before assignment
2020-07-05 21:50:32,754 [INFO] [reports]  search for file(s) starting 
2020-07-05 21:50:32,754 [INFO] [reports]  Found 0 file(s)
2020-07-05 21:50:32,754 [INFO] [reports]  Loading file(s) starting 
2020-07-05 21:50:32,754 [ERROR] [reports]  An Exception Occured
Traceback (most recent call last):
  File "C:\nora\reports.py", line 53, in reports
    df=pd.concat((pd.read_csv(file,usecols=['TimeStamp','CPU Utilization','Memory Utilization','Signaling Sessions']) for file in file_list))
  File "C:\Program Files\Python38\lib\site-packages\pandas\core\reshape\concat.py", line 271, in concat
    op = _Concatenator(
  File "C:\Program Files\Python38\lib\site-packages\pandas\core\reshape\concat.py", line 329, in __init__
    raise ValueError("No objects to concatenate")
ValueError: No objects to concatenate
2020-07-05 21:50:32,754 [INFO] [reports]  Writing report to file - K:\TEST\{name}.csv
2020-07-05 21:50:32,754 [ERROR] [reports]  An Exception Occured
Traceback (most recent call last):
  File "C:\nora\reports.py", line 74, in reports
    df.to_csv(device_name)
UnboundLocalError: local variable 'df' referenced before assignment
2020-07-05 21:50:32,762 [INFO] [reports]  search for file(s) starting 
2020-07-05 21:50:32,762 [INFO] [reports]  Found 0 file(s)
2020-07-05 21:50:32,762 [INFO] [reports]  Loading file(s) starting 
2020-07-05 21:50:32,762 [ERROR] [reports]  An Exception Occured
Traceback (most recent call last):
  File "C:\nora\reports.py", line 53, in reports
    df=pd.concat((pd.read_csv(file,usecols=['TimeStamp','CPU Utilization','Memory Utilization','Signaling Sessions']) for file in file_list))
  File "C:\Program Files\Python38\lib\site-packages\pandas\core\reshape\concat.py", line 271, in concat
    op = _Concatenator(
  File "C:\Program Files\Python38\lib\site-packages\pandas\core\reshape\concat.py", line 329, in __init__
    raise ValueError("No objects to concatenate")
ValueError: No objects to concatenate
2020-07-05 21:50:32,762 [INFO] [reports]  Writing report to file - K:\TEST\{name}.csv
2020-07-05 21:50:32,762 [ERROR] [reports]  An Exception Occured
Traceback (most recent call last):
  File "C:\nora\reports.py", line 74, in reports
    df.to_csv(device_name)
UnboundLocalError: local variable 'df' referenced before assignment
2020-07-05 21:50:32,770 [INFO] [reports]  search for file(s) starting 
2020-07-05 21:50:32,770 [INFO] [reports]  Found 0 file(s)
2020-07-05 21:50:32,770 [INFO] [reports]  Loading file(s) starting 
2020-07-05 21:50:32,770 [ERROR] [reports]  An Exception Occured
Traceback (most recent call last):
  File "C:\nora\reports.py", line 53, in reports
    df=pd.concat((pd.read_csv(file,usecols=['TimeStamp','CPU Utilization','Memory Utilization','Signaling Sessions']) for file in file_list))
  File "C:\Program Files\Python38\lib\site-packages\pandas\core\reshape\concat.py", line 271, in concat
    op = _Concatenator(
  File "C:\Program Files\Python38\lib\site-packages\pandas\core\reshape\concat.py", line 329, in __init__
    raise ValueError("No objects to concatenate")
ValueError: No objects to concatenate
2020-07-05 21:50:32,770 [INFO] [reports]  Writing report to file - K:\TEST\{name}.csv
2020-07-05 21:50:32,770 [ERROR] [reports]  An Exception Occured
Traceback (most recent call last):
  File "C:\nora\reports.py", line 74, in reports
    df.to_csv(device_name)
UnboundLocalError: local variable 'df' referenced before assignment
2020-07-05 21:50:32,774 [INFO] [reports]  search for file(s) starting 
2020-07-05 21:50:32,774 [INFO] [reports]  Found 0 file(s)
2020-07-05 21:50:32,778 [INFO] [reports]  Loading file(s) starting 
2020-07-05 21:50:32,778 [ERROR] [reports]  An Exception Occured
Traceback (most recent call last):
  File "C:\nora\reports.py", line 53, in reports
    df=pd.concat((pd.read_csv(file,usecols=['TimeStamp','CPU Utilization','Memory Utilization','Signaling Sessions']) for file in file_list))
  File "C:\Program Files\Python38\lib\site-packages\pandas\core\reshape\concat.py", line 271, in concat
    op = _Concatenator(
  File "C:\Program Files\Python38\lib\site-packages\pandas\core\reshape\concat.py", line 329, in __init__
    raise ValueError("No objects to concatenate")
ValueError: No objects to concatenate
2020-07-05 21:50:32,778 [INFO] [reports]  Writing report to file - K:\TEST\{name}.csv
2020-07-05 21:50:32,778 [ERROR] [reports]  An Exception Occured
Traceback (most recent call last):
  File "C:\nora\reports.py", line 74, in reports
    df.to_csv(device_name)
UnboundLocalError: local variable 'df' referenced before assignment
2020-07-05 21:50:32,782 [INFO] [reports]  search for file(s) starting 
2020-07-05 21:50:32,782 [INFO] [reports]  Found 0 file(s)
2020-07-05 21:50:32,782 [INFO] [reports]  Loading file(s) starting 
2020-07-05 21:50:32,782 [ERROR] [reports]  An Exception Occured
Traceback (most recent call last):
  File "C:\nora\reports.py", line 53, in reports
    df=pd.concat((pd.read_csv(file,usecols=['TimeStamp','CPU Utilization','Memory Utilization','Signaling Sessions']) for file in file_list))
  File "C:\Program Files\Python38\lib\site-packages\pandas\core\reshape\concat.py", line 271, in concat
    op = _Concatenator(
  File "C:\Program Files\Python38\lib\site-packages\pandas\core\reshape\concat.py", line 329, in __init__
    raise ValueError("No objects to concatenate")
ValueError: No objects to concatenate
2020-07-05 21:50:32,782 [INFO] [reports]  Writing report to file - K:\TEST\{name}.csv
2020-07-05 21:50:32,782 [ERROR] [reports]  An Exception Occured
Traceback (most recent call last):
  File "C:\nora\reports.py", line 74, in reports
    df.to_csv(device_name)
UnboundLocalError: local variable 'df' referenced before assignment
2020-07-05 21:50:32,782 [INFO] [<module>]  Main Script finished
2020-07-05 21:51:53,382 [INFO] [<module>]  **** repports script started ****
2020-07-05 21:51:53,390 [INFO] [reports]  search for file(s) starting 
2020-07-05 21:51:53,390 [INFO] [reports]  Found 0 file(s)
2020-07-05 21:51:53,390 [INFO] [reports]  Loading file(s) starting 
2020-07-05 21:51:53,390 [ERROR] [reports]  An Exception Occured
Traceback (most recent call last):
  File "C:\nora\reports.py", line 47, in reports
    df=pd.concat((pd.read_csv(file,usecols=['TimeStamp','CPU Utilization','Memory Utilization','Signaling Sessions']) for file in file_list))
  File "C:\Program Files\Python38\lib\site-packages\pandas\core\reshape\concat.py", line 271, in concat
    op = _Concatenator(
  File "C:\Program Files\Python38\lib\site-packages\pandas\core\reshape\concat.py", line 329, in __init__
    raise ValueError("No objects to concatenate")
ValueError: No objects to concatenate
2020-07-05 21:51:53,394 [INFO] [reports]  Writing report to file - K:\TEST\{name}.csv
2020-07-05 21:51:53,394 [ERROR] [reports]  An Exception Occured
Traceback (most recent call last):
  File "C:\nora\reports.py", line 68, in reports
    df.to_csv(device_name)
UnboundLocalError: local variable 'df' referenced before assignment
2020-07-05 21:51:53,398 [INFO] [reports]  search for file(s) starting 
2020-07-05 21:51:53,398 [INFO] [reports]  Found 0 file(s)
2020-07-05 21:51:53,398 [INFO] [reports]  Loading file(s) starting 
2020-07-05 21:51:53,398 [ERROR] [reports]  An Exception Occured
Traceback (most recent call last):
  File "C:\nora\reports.py", line 47, in reports
    df=pd.concat((pd.read_csv(file,usecols=['TimeStamp','CPU Utilization','Memory Utilization','Signaling Sessions']) for file in file_list))
  File "C:\Program Files\Python38\lib\site-packages\pandas\core\reshape\concat.py", line 271, in concat
    op = _Concatenator(
  File "C:\Program Files\Python38\lib\site-packages\pandas\core\reshape\concat.py", line 329, in __init__
    raise ValueError("No objects to concatenate")
ValueError: No objects to concatenate
2020-07-05 21:51:53,398 [INFO] [reports]  Writing report to file - K:\TEST\{name}.csv
2020-07-05 21:51:53,398 [ERROR] [reports]  An Exception Occured
Traceback (most recent call last):
  File "C:\nora\reports.py", line 68, in reports
    df.to_csv(device_name)
UnboundLocalError: local variable 'df' referenced before assignment
2020-07-05 21:51:53,402 [INFO] [reports]  search for file(s) starting 
2020-07-05 21:51:53,406 [INFO] [reports]  Found 0 file(s)
2020-07-05 21:51:53,406 [INFO] [reports]  Loading file(s) starting 
2020-07-05 21:51:53,406 [ERROR] [reports]  An Exception Occured
Traceback (most recent call last):
  File "C:\nora\reports.py", line 47, in reports
    df=pd.concat((pd.read_csv(file,usecols=['TimeStamp','CPU Utilization','Memory Utilization','Signaling Sessions']) for file in file_list))
  File "C:\Program Files\Python38\lib\site-packages\pandas\core\reshape\concat.py", line 271, in concat
    op = _Concatenator(
  File "C:\Program Files\Python38\lib\site-packages\pandas\core\reshape\concat.py", line 329, in __init__
    raise ValueError("No objects to concatenate")
ValueError: No objects to concatenate
2020-07-05 21:51:53,406 [INFO] [reports]  Writing report to file - K:\TEST\{name}.csv
2020-07-05 21:51:53,406 [ERROR] [reports]  An Exception Occured
Traceback (most recent call last):
  File "C:\nora\reports.py", line 68, in reports
    df.to_csv(device_name)
UnboundLocalError: local variable 'df' referenced before assignment
2020-07-05 21:51:53,410 [INFO] [reports]  search for file(s) starting 
2020-07-05 21:51:53,410 [INFO] [reports]  Found 0 file(s)
2020-07-05 21:51:53,410 [INFO] [reports]  Loading file(s) starting 
2020-07-05 21:51:53,410 [ERROR] [reports]  An Exception Occured
Traceback (most recent call last):
  File "C:\nora\reports.py", line 47, in reports
    df=pd.concat((pd.read_csv(file,usecols=['TimeStamp','CPU Utilization','Memory Utilization','Signaling Sessions']) for file in file_list))
  File "C:\Program Files\Python38\lib\site-packages\pandas\core\reshape\concat.py", line 271, in concat
    op = _Concatenator(
  File "C:\Program Files\Python38\lib\site-packages\pandas\core\reshape\concat.py", line 329, in __init__
    raise ValueError("No objects to concatenate")
ValueError: No objects to concatenate
2020-07-05 21:51:53,410 [INFO] [reports]  Writing report to file - K:\TEST\{name}.csv
2020-07-05 21:51:53,410 [ERROR] [reports]  An Exception Occured
Traceback (most recent call last):
  File "C:\nora\reports.py", line 68, in reports
    df.to_csv(device_name)
UnboundLocalError: local variable 'df' referenced before assignment
2020-07-05 21:51:53,414 [INFO] [reports]  search for file(s) starting 
2020-07-05 21:51:53,418 [INFO] [reports]  Found 0 file(s)
2020-07-05 21:51:53,418 [INFO] [reports]  Loading file(s) starting 
2020-07-05 21:51:53,418 [ERROR] [reports]  An Exception Occured
Traceback (most recent call last):
  File "C:\nora\reports.py", line 47, in reports
    df=pd.concat((pd.read_csv(file,usecols=['TimeStamp','CPU Utilization','Memory Utilization','Signaling Sessions']) for file in file_list))
  File "C:\Program Files\Python38\lib\site-packages\pandas\core\reshape\concat.py", line 271, in concat
    op = _Concatenator(
  File "C:\Program Files\Python38\lib\site-packages\pandas\core\reshape\concat.py", line 329, in __init__
    raise ValueError("No objects to concatenate")
ValueError: No objects to concatenate
2020-07-05 21:51:53,418 [INFO] [reports]  Writing report to file - K:\TEST\{name}.csv
2020-07-05 21:51:53,418 [ERROR] [reports]  An Exception Occured
Traceback (most recent call last):
  File "C:\nora\reports.py", line 68, in reports
    df.to_csv(device_name)
UnboundLocalError: local variable 'df' referenced before assignment
2020-07-05 21:51:53,422 [INFO] [reports]  search for file(s) starting 
2020-07-05 21:51:53,422 [INFO] [reports]  Found 0 file(s)
2020-07-05 21:51:53,422 [INFO] [reports]  Loading file(s) starting 
2020-07-05 21:51:53,422 [ERROR] [reports]  An Exception Occured
Traceback (most recent call last):
  File "C:\nora\reports.py", line 47, in reports
    df=pd.concat((pd.read_csv(file,usecols=['TimeStamp','CPU Utilization','Memory Utilization','Signaling Sessions']) for file in file_list))
  File "C:\Program Files\Python38\lib\site-packages\pandas\core\reshape\concat.py", line 271, in concat
    op = _Concatenator(
  File "C:\Program Files\Python38\lib\site-packages\pandas\core\reshape\concat.py", line 329, in __init__
    raise ValueError("No objects to concatenate")
ValueError: No objects to concatenate
2020-07-05 21:51:53,422 [INFO] [reports]  Writing report to file - K:\TEST\{name}.csv
2020-07-05 21:51:53,422 [ERROR] [reports]  An Exception Occured
Traceback (most recent call last):
  File "C:\nora\reports.py", line 68, in reports
    df.to_csv(device_name)
UnboundLocalError: local variable 'df' referenced before assignment
2020-07-05 21:51:53,422 [INFO] [<module>]  Main Script finished
2020-07-05 21:56:50,348 [INFO] [<module>]  **** reports script started ****
2020-07-05 21:56:50,356 [INFO] [reports]  search for file(s) starting 
2020-07-05 21:56:50,356 [INFO] [reports]  Found 0 file(s)
2020-07-05 21:56:50,356 [INFO] [reports]  Loading file(s) starting 
2020-07-05 21:56:50,356 [ERROR] [reports]  An Exception Occured
Traceback (most recent call last):
  File "C:\nora\reports.py", line 47, in reports
    df=pd.concat((pd.read_csv(file,usecols=['TimeStamp','CPU Utilization','Memory Utilization','Signaling Sessions']) for file in file_list))
  File "C:\Program Files\Python38\lib\site-packages\pandas\core\reshape\concat.py", line 271, in concat
    op = _Concatenator(
  File "C:\Program Files\Python38\lib\site-packages\pandas\core\reshape\concat.py", line 329, in __init__
    raise ValueError("No objects to concatenate")
ValueError: No objects to concatenate
2020-07-05 21:56:50,360 [INFO] [reports]  Writing report to file - K:\REPORTS\m-cba-nsw-bellavista-sbc01_m-cba-nsw-bellavista-sbc02.csv
2020-07-05 21:56:50,360 [ERROR] [reports]  An Exception Occured
Traceback (most recent call last):
  File "C:\nora\reports.py", line 68, in reports
    df.to_csv(device_name)
UnboundLocalError: local variable 'df' referenced before assignment
2020-07-05 21:56:50,364 [INFO] [reports]  search for file(s) starting 
2020-07-05 21:56:50,364 [INFO] [reports]  Found 0 file(s)
2020-07-05 21:56:50,364 [INFO] [reports]  Loading file(s) starting 
2020-07-05 21:56:50,364 [ERROR] [reports]  An Exception Occured
Traceback (most recent call last):
  File "C:\nora\reports.py", line 47, in reports
    df=pd.concat((pd.read_csv(file,usecols=['TimeStamp','CPU Utilization','Memory Utilization','Signaling Sessions']) for file in file_list))
  File "C:\Program Files\Python38\lib\site-packages\pandas\core\reshape\concat.py", line 271, in concat
    op = _Concatenator(
  File "C:\Program Files\Python38\lib\site-packages\pandas\core\reshape\concat.py", line 329, in __init__
    raise ValueError("No objects to concatenate")
ValueError: No objects to concatenate
2020-07-05 21:56:50,364 [INFO] [reports]  Writing report to file - K:\REPORTS\m-cba-nsw-bellavista-sbc03.csv
2020-07-05 21:56:50,364 [ERROR] [reports]  An Exception Occured
Traceback (most recent call last):
  File "C:\nora\reports.py", line 68, in reports
    df.to_csv(device_name)
UnboundLocalError: local variable 'df' referenced before assignment
2020-07-05 21:56:50,372 [INFO] [reports]  search for file(s) starting 
2020-07-05 21:56:50,372 [INFO] [reports]  Found 0 file(s)
2020-07-05 21:56:50,372 [INFO] [reports]  Loading file(s) starting 
2020-07-05 21:56:50,372 [ERROR] [reports]  An Exception Occured
Traceback (most recent call last):
  File "C:\nora\reports.py", line 47, in reports
    df=pd.concat((pd.read_csv(file,usecols=['TimeStamp','CPU Utilization','Memory Utilization','Signaling Sessions']) for file in file_list))
  File "C:\Program Files\Python38\lib\site-packages\pandas\core\reshape\concat.py", line 271, in concat
    op = _Concatenator(
  File "C:\Program Files\Python38\lib\site-packages\pandas\core\reshape\concat.py", line 329, in __init__
    raise ValueError("No objects to concatenate")
ValueError: No objects to concatenate
2020-07-05 21:56:50,372 [INFO] [reports]  Writing report to file - K:\REPORTS\m-cba-nsw-bellavista-sbc04.csv
2020-07-05 21:56:50,372 [ERROR] [reports]  An Exception Occured
Traceback (most recent call last):
  File "C:\nora\reports.py", line 68, in reports
    df.to_csv(device_name)
UnboundLocalError: local variable 'df' referenced before assignment
2020-07-05 21:56:50,380 [INFO] [reports]  search for file(s) starting 
2020-07-05 21:56:50,380 [INFO] [reports]  Found 0 file(s)
2020-07-05 21:56:50,380 [INFO] [reports]  Loading file(s) starting 
2020-07-05 21:56:50,380 [ERROR] [reports]  An Exception Occured
Traceback (most recent call last):
  File "C:\nora\reports.py", line 47, in reports
    df=pd.concat((pd.read_csv(file,usecols=['TimeStamp','CPU Utilization','Memory Utilization','Signaling Sessions']) for file in file_list))
  File "C:\Program Files\Python38\lib\site-packages\pandas\core\reshape\concat.py", line 271, in concat
    op = _Concatenator(
  File "C:\Program Files\Python38\lib\site-packages\pandas\core\reshape\concat.py", line 329, in __init__
    raise ValueError("No objects to concatenate")
ValueError: No objects to concatenate
2020-07-05 21:56:50,380 [INFO] [reports]  Writing report to file - K:\REPORTS\m-cba-nsw-burwood-sbc01_m-cba-nsw-burwood-sbc02.csv
2020-07-05 21:56:50,380 [ERROR] [reports]  An Exception Occured
Traceback (most recent call last):
  File "C:\nora\reports.py", line 68, in reports
    df.to_csv(device_name)
UnboundLocalError: local variable 'df' referenced before assignment
2020-07-05 21:56:50,388 [INFO] [reports]  search for file(s) starting 
2020-07-05 21:56:50,388 [INFO] [reports]  Found 0 file(s)
2020-07-05 21:56:50,388 [INFO] [reports]  Loading file(s) starting 
2020-07-05 21:56:50,388 [ERROR] [reports]  An Exception Occured
Traceback (most recent call last):
  File "C:\nora\reports.py", line 47, in reports
    df=pd.concat((pd.read_csv(file,usecols=['TimeStamp','CPU Utilization','Memory Utilization','Signaling Sessions']) for file in file_list))
  File "C:\Program Files\Python38\lib\site-packages\pandas\core\reshape\concat.py", line 271, in concat
    op = _Concatenator(
  File "C:\Program Files\Python38\lib\site-packages\pandas\core\reshape\concat.py", line 329, in __init__
    raise ValueError("No objects to concatenate")
ValueError: No objects to concatenate
2020-07-05 21:56:50,388 [INFO] [reports]  Writing report to file - K:\REPORTS\m-cba-nsw-burwood-sbc03.csv
2020-07-05 21:56:50,388 [ERROR] [reports]  An Exception Occured
Traceback (most recent call last):
  File "C:\nora\reports.py", line 68, in reports
    df.to_csv(device_name)
UnboundLocalError: local variable 'df' referenced before assignment
2020-07-05 21:56:50,392 [INFO] [reports]  search for file(s) starting 
2020-07-05 21:56:50,392 [INFO] [reports]  Found 0 file(s)
2020-07-05 21:56:50,392 [INFO] [reports]  Loading file(s) starting 
2020-07-05 21:56:50,392 [ERROR] [reports]  An Exception Occured
Traceback (most recent call last):
  File "C:\nora\reports.py", line 47, in reports
    df=pd.concat((pd.read_csv(file,usecols=['TimeStamp','CPU Utilization','Memory Utilization','Signaling Sessions']) for file in file_list))
  File "C:\Program Files\Python38\lib\site-packages\pandas\core\reshape\concat.py", line 271, in concat
    op = _Concatenator(
  File "C:\Program Files\Python38\lib\site-packages\pandas\core\reshape\concat.py", line 329, in __init__
    raise ValueError("No objects to concatenate")
ValueError: No objects to concatenate
2020-07-05 21:56:50,392 [INFO] [reports]  Writing report to file - K:\REPORTS\m-cba-nsw-burwood-sbc04.csv
2020-07-05 21:56:50,392 [ERROR] [reports]  An Exception Occured
Traceback (most recent call last):
  File "C:\nora\reports.py", line 68, in reports
    df.to_csv(device_name)
UnboundLocalError: local variable 'df' referenced before assignment
2020-07-05 21:56:50,396 [INFO] [<module>]  **** report script finished ****

